<sdf version='1.6'>
  <model name='Aero4river'>
    <link name='base_link'>
      <pose>0 0 0 0 -0 0</pose>
      <inertial>
        <pose >0 0 0.124229 0 -0 0</pose>
        <mass>30.4491</mass>
        <inertia>
          <ixx>3.7</ixx>
          <ixy>0</ixy>
          <ixz>0</ixz>
          <iyy>4.8</iyy>
          <iyz>0</iyz>
          <izz>3.74</izz>
        </inertia>
      </inertial>

      <!-- CASCO 1-->
      <collision name='Casco_centro'>
        <pose>-0.1 0.353 0.14 3.14159 1.57079 3.14159</pose>
        <geometry>
          <cylinder>
            <length>0.7</length>
            <radius>0.14</radius>
          </cylinder>
        </geometry>
      </collision>
      <collision name='Casco_centro_ponta1'>
        <pose>0.325 0.353 0.21 0 1.57079 0</pose>
        <geometry>
          <cylinder>
            <length>0.15</length>
            <radius>0.07</radius>
          </cylinder>
        </geometry>-0.2
      </collision>
      <collision name='Casco_centro_ponta2'>
        <pose>0.45 0.353 0.23 0 1.57079 0</pose>
        <geometry>
          <cylinder>
            <length>0.1</length>
            <radius>0.05</radius>
          </cylinder>
        </geometry>
      </collision>
      <collision name='Casco_centro_back1'>
        <pose>-0.5 0.353 0.21 0 1.57079 0</pose>
        <geometry>
          <cylinder>
            <length>0.15</length>
            <radius>0.07</radius>
          </cylinder>
        </geometry>
      </collision>

      <!-- CASCO 2-->
      <collision name='Casco_centro_direita'>
        <pose>-0.1 -0.353 0.14 3.14159 1.57079 3.14159</pose>
        <geometry>
          <cylinder>
            <length>0.7</length>
            <radius>0.14</radius>
          </cylinder>
        </geometry>
      </collision>
      <collision name='Casco_centro_ponta1_direita'>
        <pose>0.325 -0.353 0.21 0 1.57079 0</pose>
        <geometry>
          <cylinder>
            <length>0.15</length>
            <radius>0.07</radius>
          </cylinder>
        </geometry>-0.2
      </collision>
      <collision name='Casco_centro_ponta2_direita'>
        <pose>0.45 -0.353 0.23 0 1.57079 0</pose>
        <geometry>
          <cylinder>
            <length>0.1</length>
            <radius>0.05</radius>
          </cylinder>
        </geometry>
      </collision>
      <collision name='Casco_centro_back1_direita'>
        <pose>-0.5 -0.353 0.21 0 1.57079 0</pose>
        <geometry>
          <cylinder>
            <length>0.15</length>
            <radius>0.07</radius>
          </cylinder>
        </geometry>
      </collision>

      <!--BARRAS MOTORES-->
      <collision name='Barra_motor_1'>
        <pose>0.342 -0.35 0.40 0 0 0</pose>
        <geometry>
          <cylinder>
            <length>0.3</length> <!-- barra lateral transversal frontal -->
            <radius>0.007</radius>
          </cylinder>
        </geometry>
      </collision>
      <collision name='Barra_motor_2'>
        <pose>-0.4 0.35 0.40 0 0 0</pose>
        <geometry>
          <cylinder>
            <length>0.3</length> <!-- barra lateral transversal frontal -->
            <radius>0.007</radius>
          </cylinder>
        </geometry>
      </collision>
      <collision name='Barra_motor_3'>
        <pose>0.342 0.35 0.40 0 0 0</pose>
        <geometry>
          <cylinder>
            <length>0.3</length> <!-- barra lateral transversal frontal -->
            <radius>0.007</radius>
          </cylinder>
        </geometry>
      </collision>
      <collision name='Barra_motor_4'>
        <pose>-0.4 -0.35 0.40 0 0 0</pose>
        <geometry>
          <cylinder>
            <length>0.3</length> <!-- barra lateral transversal frontal -->
            <radius>0.007</radius>
          </cylinder>
        </geometry>
      </collision>

      <collision name='barra_transversal_frontal'>
        <pose>0.19 0 0.285 0 1.5707 1.5707</pose>
        <geometry>
          <cylinder>
            <length>0.9</length> <!-- barra lateral transversal frontal -->
            <radius>0.011</radius>
          </cylinder>
        </geometry>
      </collision>
      <collision name='barra_transversal_traseira'>
        <pose>-0.245 0 0.285 0 1.5707 1.5707</pose>
        <geometry>
          <cylinder>
            <length>0.9</length> <!-- barra lateral transversal traseira -->
            <radius>0.011</radius>
          </cylinder>
        </geometry>
      </collision>

      <collision name='barra_longitudinal_direita'>
        <pose>0.06 -0.08 0.35 0 1.5707 0</pose>
        <geometry>
          <cylinder>
            <length>1</length>
            <radius>0.011</radius>
          </cylinder>
        </geometry>
      </collision>
      <collision name='barra_longitudinal_esquerda'>
        <pose>0.06 0.08 0.35 0 1.5707 0</pose>
        <geometry>
          <cylinder>
            <length>1</length>
            <radius>0.011</radius>
          </cylinder>
        </geometry>
      </collision>

      <collision name='Caixa_Eletronica'>
        <pose>0.21 0 0.45 0 -0 0</pose>
        <geometry>
          <box>
            <size>0.26 0.20 0.17 </size> <!-- Caixa Eletronica-->
          </box>
        </geometry>
      </collision>
      <collision name='Caixa_Baterias'>
        <pose>-0.11 0 0.435 0 -0 0</pose>
        <geometry>
          <box>
            <size>0.20 0.3 0.14 </size> <!-- Caixa das Baterias-->
          </box>
        </geometry>
      </collision>

      <visual name='Aero4river_visual'>
        <pose>0 0 0 0 -0 0</pose>
        <geometry>
          <mesh>
            <scale>1 1 1</scale>
            <uri>model://Aero4river/meshesRiver/Barco.dae</uri>
          </mesh>
        </geometry>
      </visual>
    </link>

    <!-- HELICES -->
    <link name='Helice_1'>
      <pose>0.402 -0.35 0.55 0 1.57075 0</pose>
      <inertial>
        <pose>0 0 0 0 -0 0</pose>
        <mass>0.024</mass>
        <inertia>
          <ixx>0.0000015098</ixx>
          <ixy>0</ixy>
          <ixz>-0.00000243351</ixz>
          <iyy>0.0002306966</iyy>
          <iyz>0</iyz>
          <izz>0.00022937495</izz>
        </inertia>
      </inertial>
      <collision name='Helice_1_colision'>
        <pose>0 0 0 0 -0 0</pose>
        <geometry>
          <cylinder>
            <length>0.003</length>
            <radius>0.19</radius>
          </cylinder>
        </geometry>
      </collision>
      <visual name='Helice_1_visual'>
        <pose>0 0 0 1.57075 0 1.57075</pose>
        <geometry>
          <mesh>
            <scale>1 1 1</scale>
            <uri>model://Aero4river/meshesRiver/helice.dae</uri>
          </mesh>
        </geometry>
      </visual>
    </link>

    <link name='Helice_2'>
      <pose>-0.338 0.35 0.55 0 1.57075 0</pose>
      <inertial>
        <pose>0 0 0 0 -0 0</pose>
        <mass>0.024</mass>
        <inertia>
          <ixx>0.0000015098</ixx>
          <ixy>0</ixy>
          <ixz>-0.00000243351</ixz>
          <iyy>0.0002306966</iyy>
          <iyz>0</iyz>
          <izz>0.00022937495</izz>
        </inertia>
      </inertial>
      <collision name='Helice_2_colision'>
        <pose>0 0 0 0 -0 0</pose>
        <geometry>
          <cylinder>
            <length>0.003</length>
            <radius>0.19</radius>
          </cylinder>
        </geometry>
      </collision>
      <visual name='Helice_2_visual'>
        <pose>0 0 0  1.57075 0 1.57075</pose>
        <geometry>
          <mesh>
            <scale>1 1 1</scale>
            <uri>model://Aero4river/meshesRiver/helice.dae</uri>
          </mesh>
        </geometry>
      </visual>
    </link>

    <link name='Helice_3'>
      <pose>0.402 0.35 0.55 0 1.57075 0</pose>
      <inertial>
        <pose>0 0 0 0 -0 0</pose>
        <mass>0.024</mass>
        <inertia>
          <ixx>0.0000015098</ixx>
          <ixy>0</ixy>
          <ixz>-0.00000243351</ixz>
          <iyy>0.0002306966</iyy>
          <iyz>0</iyz>
          <izz>0.00022937495</izz>
        </inertia>
      </inertial>
      <collision name='Helice_3_colision'>
        <pose>0 0 0 0 -0 0</pose>
        <geometry>
          <cylinder>
            <length>0.003</length>
            <radius>0.19</radius>
          </cylinder>
        </geometry>
      </collision>
      <visual name='Helice_3_visual'>
        <pose>0 0 0 1.57075 0 1.57075</pose>
        <geometry>
          <mesh>
            <scale>1 1 1</scale>
            <uri>model://Aero4river/meshesRiver/helice.dae</uri>
          </mesh>
        </geometry>
      </visual>
    </link>

    <link name='Helice_4'>
      <pose>-0.338 -0.35 0.55 0 1.57075 0</pose>
      <inertial>
        <pose>0 0 0 0 -0 0</pose>
        <mass>0.024</mass>
        <inertia>
          <ixx>0.0000015098</ixx>
          <ixy>0</ixy>
          <ixz>-0.00000243351</ixz>
          <iyy>0.0002306966</iyy>
          <iyz>0</iyz>
          <izz>0.00022937495</izz>
        </inertia>
      </inertial>
      <collision name='Helice_4_colision'>
        <pose>0 0 0 0 -0 0</pose>
        <geometry>
          <cylinder>
            <length>0.003</length>
            <radius>0.19</radius>
          </cylinder>
        </geometry>
      </collision>
      <visual name='Helice_4_visual'>
        <pose>0 0 0 1.57075 0 1.57075</pose>
        <geometry>
          <mesh>
            <scale>1 1 1</scale>
            <uri>model://Aero4river/meshesRiver/helice.dae</uri>
          </mesh>
        </geometry>
      </visual>
    </link>

    <!-- MOTOR -->
    <link name='Motor_1'>
     <pose>0.34 -0.35 0.55 0 1.57075 0</pose>
      <inertial>
        <pose>0 0 0 0 0 0</pose>
        <mass>0.87329</mass>
        <inertia>
          <ixx>0.00532259139</ixx>
          <ixy>0</ixy>
          <ixz>0</ixz>
          <iyy>0.00363239675</iyy>
          <iyz>-0.00067637070</iyz>
          <izz>0.00234468738</izz>
        </inertia>
      </inertial>
      <collision name='Motor_1_collision'>
        <pose>0 0 -0.04 0 0 0</pose>
        <geometry>
          <cylinder>
            <length>0.20</length>
            <radius>0.05</radius>
          </cylinder>
        </geometry>
      </collision>
      <visual name='motor_1_visual'>
        <pose>0 0 0 0 -1.57075 0</pose>
        <geometry>
          <mesh>
            <scale>1 1 1</scale>
            <uri>model://Aero4river/meshesRiver/motor.dae</uri>
          </mesh>
        </geometry>
      </visual>
    </link>

    <link name='Motor_2'>
     <pose>-0.4 0.35 0.55 0 1.57075 0</pose>
      <inertial>
        <pose>0 0 0 0 0 0</pose>
       <mass>0.87329</mass>
        <inertia>
          <ixx>0.00532259139</ixx>
          <ixy>0</ixy>
          <ixz>0</ixz>
          <iyy>0.00363239675</iyy>
          <iyz>-0.00067637070</iyz>
          <izz>0.00234468738</izz>
        </inertia>
      </inertial>
      <collision name='Motor_2_collision'>
        <pose>0 0 -0.04 0 0 0</pose>
        <geometry>
          <cylinder>
            <length>0.20</length>
            <radius>0.05</radius>
          </cylinder>
        </geometry>
      </collision>
      <visual name='motor_2_visual'>
        <pose>0 0 0 0 -1.57075 0</pose>
        <geometry>
          <mesh>
            <scale>1 1 1</scale>
            <uri>model://Aero4river/meshesRiver/motor.dae</uri>
          </mesh>
        </geometry>
      </visual>
    </link>

    <link name='Motor_3'>
     <pose>0.342 0.35 0.55 0 1.57075 0</pose>
      <inertial>
        <pose>0 0 0 0 0 0</pose>
        <mass>0.87329</mass>
        <inertia>
          <ixx>0.00532259139</ixx>
          <ixy>0</ixy>
          <ixz>0</ixz>
          <iyy>0.00363239675</iyy>
          <iyz>-0.00067637070</iyz>
          <izz>0.00234468738</izz>
        </inertia>
      </inertial>
      <collision name='Motor_3_collision'>
        <pose>0 0 -0.04 0 0 0</pose>
        <geometry>
          <cylinder>
            <length>0.20</length>
            <radius>0.05</radius>
          </cylinder>
        </geometry>
      </collision>
      <visual name='motor_3_visual'>
        <pose>0 0 0 0 -1.57075 0</pose>
        <geometry>
          <mesh>
            <scale>1 1 1</scale>
            <uri>model://Aero4river/meshesRiver/motor.dae</uri>
          </mesh>
        </geometry>
      </visual>
    </link>

    <link name='Motor_4'>
     <pose>-0.4 -0.35 0.55 0 1.57075 0</pose>
      <inertial>
        <pose>0 0 0 0 0 0</pose>
        <mass>0.87329</mass>
        <inertia>
          <ixx>0.00532259139</ixx>
          <ixy>0</ixy>
          <ixz>0</ixz>
          <iyy>0.00363239675</iyy>
          <iyz>-0.00067637070</iyz>
          <izz>0.00234468738</izz>
        </inertia>
      </inertial>
      <collision name='Motor_4_collision'>
        <pose>0 0 -0.04 0 0 0</pose>
        <geometry>
          <cylinder>
            <length>0.20</length>
            <radius>0.05</radius>
          </cylinder>
        </geometry>
      </collision>
      <visual name='motor_4_visual'>
        <pose>0 0 0 0 -1.57075 0</pose>
        <geometry>
          <mesh>
            <scale>1 1 1</scale>
            <uri>model://Aero4river/meshesRiver/motor.dae</uri>
          </mesh>
        </geometry>
      </visual>
    </link>

    <!-- Juntas Motor -->
    <joint name='Base_engine_1' type='revolute'>
      <child>Motor_1</child>
      <parent>base_link</parent>
      <axis>
        <xyz>0 0 1</xyz>
        <limit>
          <lower>-1e+16</lower>
          <upper>1e+16</upper>
        </limit>
        <dynamics>
          <!-- <damping>0.05</damping>
          <friction>0.05</friction> -->
          <spring_reference>0</spring_reference>
          <spring_stiffness>0</spring_stiffness>
        </dynamics>
        <use_parent_model_frame>1</use_parent_model_frame>
      </axis>
    </joint>

    <joint name='Base_engine_2' type='revolute'>
      <child>Motor_2</child>
      <parent>base_link</parent>
      <axis>
        <xyz>0 0 1</xyz>
        <limit>
          <lower>-1e+16</lower>
          <upper>1e+16</upper>
        </limit>
        <dynamics>
          <!-- <damping>0.05</damping>
          <friction>0.05</friction> -->
          <spring_reference>0</spring_reference>
          <spring_stiffness>0</spring_stiffness>
        </dynamics>
        <use_parent_model_frame>1</use_parent_model_frame>
      </axis>
    </joint>

    <joint name='Base_engine_3' type='revolute'>
      <child>Motor_3</child>
      <parent>base_link</parent>
      <axis>
        <xyz>0 0 1</xyz>
        <limit>
          <lower>-1e+16</lower>
          <upper>1e+16</upper>
        </limit>
        <dynamics>
          <!-- <damping>0.05</damping>
          <friction>0.05</friction> -->
          <spring_reference>0</spring_reference>
          <spring_stiffness>0</spring_stiffness>
        </dynamics>
        <use_parent_model_frame>1</use_parent_model_frame>
      </axis>
    </joint>

    <joint name='Base_engine_4' type='revolute'>
      <child>Motor_4</child>
      <parent>base_link</parent>
      <axis>
        <xyz>0 0 1</xyz>
        <limit>
          <lower>-1e+16</lower>
          <upper>1e+16</upper>
        </limit>
        <dynamics>
          <!-- <damping>0.05</damping>
          <friction>0.05</friction> -->
          <spring_reference>0</spring_reference>
          <spring_stiffness>0</spring_stiffness>
        </dynamics>
        <use_parent_model_frame>1</use_parent_model_frame>
      </axis>
    </joint>

    <!-- Juntas Helices -->
    <joint name='Engine_helice_1' type='revolute'>
      <child>Helice_1</child>
      <parent>Motor_1</parent>
      <axis>
        <xyz>1 0 0</xyz>
        <limit>
          <lower>-1e+16</lower>
          <upper>1e+16</upper>
        </limit>
        <dynamics>
           <!-- <damping>0.05</damping>
          <friction>0.05</friction> -->
          <spring_reference>0</spring_reference>
          <spring_stiffness>0</spring_stiffness>
        </dynamics>
        <use_parent_model_frame>1</use_parent_model_frame>
      </axis>
    </joint>

    <joint name='Engine_helice_2' type='revolute'>
      <child>Helice_2</child>
      <parent>Motor_2</parent>
      <axis>
        <xyz>1 0 0</xyz>
        <limit>
          <lower>-1e+16</lower>
          <upper>1e+16</upper>
        </limit>
        <dynamics>
           <!-- <damping>0.05</damping>
          <friction>0.05</friction> -->
          <spring_reference>0</spring_reference>
          <spring_stiffness>0</spring_stiffness>
        </dynamics>
        <use_parent_model_frame>1</use_parent_model_frame>
      </axis>
    </joint>

    <joint name='Engine_helice_3' type='revolute'>
      <child>Helice_3</child>
      <parent>Motor_3</parent>
      <axis>
        <xyz>1 0 0</xyz>
        <limit>
          <lower>-1e+16</lower>
          <upper>1e+16</upper>
        </limit>
        <dynamics>
           <!-- <damping>0.05</damping>
          <friction>0.05</friction> -->
          <spring_reference>0</spring_reference>
          <spring_stiffness>0</spring_stiffness>
        </dynamics>
        <use_parent_model_frame>1</use_parent_model_frame>
      </axis>
    </joint>

    <joint name='Engine_helice_4' type='revolute'>
      <child>Helice_4</child>
      <parent>Motor_4</parent>
      <axis>
        <xyz>1 0 0</xyz>
        <limit>
          <lower>-1e+16</lower>
          <upper>1e+16</upper>
        </limit>
        <dynamics>
           <!-- <damping>0.05</damping>
          <friction>0.05</friction> -->
          <spring_reference>0</spring_reference>
          <spring_stiffness>0</spring_stiffness>
        </dynamics>
        <use_parent_model_frame>1</use_parent_model_frame>
      </axis>
    </joint>


    <link name='Aero4river/imu_link'>
      <pose>0 0 0 0 0 0</pose>
      <inertial>
        <pose>0 0 0 0 0 0</pose>
        <mass>0.015</mass>
        <inertia>
          <ixx>1e-05</ixx>
          <ixy>0</ixy>
          <ixz>0</ixz>
          <iyy>1e-05</iyy>
          <iyz>0</iyz>
          <izz>1e-05</izz>
        </inertia>
      </inertial>
    </link>

    <joint name='right_engine_propeller_joint' type='revolute'>
      <child>right_propeller_link</child>
      <parent>base_link</parent>
      <axis>
        <xyz>1 0 0</xyz>
        <limit>
          <lower>-1e+16</lower>
          <upper>1e+16</upper>
        </limit>
        <dynamics>
          <!-- <damping>0.05</damping>
          <friction>0.05</friction> -->
          <spring_reference>0</spring_reference>
          <spring_stiffness>0</spring_stiffness>
        </dynamics>
        <use_parent_model_frame>1</use_parent_model_frame>
      </axis>
    </joint>

    <joint name='boat/imu_joint' type='revolute'>
      <child>Aero4river/imu_link</child>
      <parent>base_link</parent>
      <axis>
        <xyz>1 0 0</xyz>
        <limit>
          <lower>0</lower>
          <upper>0</upper>
          <effort>0</effort>
          <velocity>0</velocity>
        </limit>
        <dynamics>
          <spring_reference>0</spring_reference>
          <spring_stiffness>0</spring_stiffness>
        </dynamics>
        <use_parent_model_frame>1</use_parent_model_frame>
      </axis>
    </joint>

    <include>
      <uri>model://gps</uri>
      <pose>0 0 0.12 0 0 0</pose>
      <name>gps</name>
    </include>

    <joint name='gps_joint' type='fixed'>
      <child>gps::link</child>
      <parent>base_link</parent>
    </joint>


    <plugin name='gazebo_imu_plugin' filename='libgazebo_imu_plugin.so'>
      <robotNamespace></robotNamespace>
      <linkName>Aero4river/imu_link</linkName>
      <imuTopic>/imu</imuTopic>
      <gyroscopeNoiseDensity>0.0003394</gyroscopeNoiseDensity>
      <gyroscopeRandomWalk>3.8785e-05</gyroscopeRandomWalk>
      <gyroscopeBiasCorrelationTime>1000.0</gyroscopeBiasCorrelationTime>
      <gyroscopeTurnOnBiasSigma>0.0087</gyroscopeTurnOnBiasSigma>
      <accelerometerNoiseDensity>0.004</accelerometerNoiseDensity>
      <accelerometerRandomWalk>0.006</accelerometerRandomWalk>
      <accelerometerBiasCorrelationTime>300.0</accelerometerBiasCorrelationTime>
      <accelerometerTurnOnBiasSigma>0.196</accelerometerTurnOnBiasSigma>
    </plugin>

    <plugin name='magnetometer_plugin' filename='libgazebo_magnetometer_plugin.so'>
      <robotNamespace/>
      <pubRate>100</pubRate>
      <noiseDensity>0.0004</noiseDensity>
      <randomWalk>6.4e-06</randomWalk>
      <biasCorrelationTime>600</biasCorrelationTime>
      <magTopic>/mag</magTopic>
    </plugin>

    <plugin name='barometer_plugin' filename='libgazebo_barometer_plugin.so'>
      <robotNamespace/>
      <pubRate>50</pubRate>
      <baroTopic>/baro</baroTopic>
    </plugin>

    <static>0</static>
    <plugin name='motor1_model' filename='libgazebo_motor_model.so'>
      <robotNamespace></robotNamespace>
      <jointName>Engine_helice_1</jointName>
      <linkName>Helice_1</linkName>
      <turningDirection>ccw</turningDirection>
      <timeConstantUp>0.0125</timeConstantUp>
      <timeConstantDown>0.025</timeConstantDown>
      <maxRotVelocity>1100</maxRotVelocity>
      <motorConstant>8.54858e-03</motorConstant>
      <momentConstant>0.01</momentConstant>
      <commandSubTopic>/gazebo/command/motor_speed</commandSubTopic>
      <motorNumber>0</motorNumber>
      <rotorDragCoefficient>0.000806428</rotorDragCoefficient>
      <rollingMomentCoefficient>1e-06</rollingMomentCoefficient>
      <motorSpeedPubTopic>/motor_speed/0</motorSpeedPubTopic>
      <rotorVelocitySlowdownSim>10</rotorVelocitySlowdownSim>
    </plugin>

    <plugin name='motor2_model' filename='libgazebo_motor_model.so'>
      <robotNamespace></robotNamespace>
      <jointName>Engine_helice_2</jointName>
      <linkName>Helice_2</linkName>
      <turningDirection>ccw</turningDirection>
      <timeConstantUp>0.0125</timeConstantUp>
      <timeConstantDown>0.025</timeConstantDown>
      <maxRotVelocity>1100</maxRotVelocity>
      <motorConstant>8.54858e-03</motorConstant>
      <momentConstant>0.01</momentConstant>
      <commandSubTopic>/gazebo/command/motor_speed</commandSubTopic>
      <motorNumber>1</motorNumber>
      <rotorDragCoefficient>0.000806428</rotorDragCoefficient>
      <rollingMomentCoefficient>1e-06</rollingMomentCoefficient>
      <motorSpeedPubTopic>/motor_speed/1</motorSpeedPubTopic>
      <rotorVelocitySlowdownSim>10</rotorVelocitySlowdownSim>
    </plugin>

    <plugin name='motor3_model' filename='libgazebo_motor_model.so'>
      <robotNamespace></robotNamespace>
      <jointName>Engine_helice_3</jointName>
      <linkName>Helice_3</linkName>
      <turningDirection>cw</turningDirection>
      <timeConstantUp>0.0125</timeConstantUp>
      <timeConstantDown>0.025</timeConstantDown>
      <maxRotVelocity>1100</maxRotVelocity>
      <motorConstant>8.54858e-03</motorConstant>
      <momentConstant>0.01</momentConstant>
      <commandSubTopic>/gazebo/command/motor_speed</commandSubTopic>
      <motorNumber>2</motorNumber>
      <rotorDragCoefficient>0.000806428</rotorDragCoefficient>
      <rollingMomentCoefficient>1e-06</rollingMomentCoefficient>
      <motorSpeedPubTopic>/motor_speed/1</motorSpeedPubTopic>
      <rotorVelocitySlowdownSim>10</rotorVelocitySlowdownSim>
    </plugin>

    <plugin name='motor4_model' filename='libgazebo_motor_model.so'>
      <robotNamespace></robotNamespace>
      <jointName>Engine_helice_4</jointName>
      <linkName>Helice_4</linkName>
      <turningDirection>cw</turningDirection>
      <timeConstantUp>0.0125</timeConstantUp>
      <timeConstantDown>0.025</timeConstantDown>
      <maxRotVelocity>1100</maxRotVelocity>
      <motorConstant>8.54858e-03</motorConstant>
      <momentConstant>0.01</momentConstant>
      <commandSubTopic>/gazebo/command/motor_speed</commandSubTopic>
      <motorNumber>3</motorNumber>
      <rotorDragCoefficient>0.000806428</rotorDragCoefficient>
      <rollingMomentCoefficient>1e-06</rollingMomentCoefficient>
      <motorSpeedPubTopic>/motor_speed/1</motorSpeedPubTopic>
      <rotorVelocitySlowdownSim>10</rotorVelocitySlowdownSim>
    </plugin>

    <plugin name='usv_dynamics_wamv_dynamics_plugin' filename='libgazebo_usv_dynamics_plugin.so'>
      <bodyName>base_link</bodyName>
      <waterLevel>0</waterLevel>
      <waterDensity>997.8</waterDensity>
      <xDotU>0.0</xDotU>
      <yDotV>0.0</yDotV>
      <nDotR>0.0</nDotR>
      <xU>51.3</xU>
      <xUU>72.4</xUU>
      <yV>40.0</yV>
      <yVV>0.0</yVV>
      <zW>500.0</zW>
      <kP>50.0</kP>
      <mQ>50.0</mQ>
      <nR>400.0</nR>
      <nRR>0.0</nRR>
      <hullRadius>0.213</hullRadius>
      <boatWidth>1</boatWidth>
      <boatLength>1.2</boatLength>
      <length_n>2</length_n>
      <wave_model>ocean_waves</wave_model>
    </plugin>

    <plugin name='mavlink_interface' filename='libgazebo_mavlink_interface.so'>
      <robotNamespace></robotNamespace>
      <imuSubTopic>/imu</imuSubTopic>
      <magSubTopic>/mag</magSubTopic>
      <baroSubTopic>/baro</baroSubTopic>
      <mavlink_addr>INADDR_ANY</mavlink_addr>
      <mavlink_tcp_port>4560</mavlink_tcp_port>
      <mavlink_udp_port>14560</mavlink_udp_port>
      <serialEnabled>0</serialEnabled>
      <serialDevice>/dev/ttyACM0</serialDevice>
      <baudRate>921600</baudRate>
      <qgc_addr>INADDR_ANY</qgc_addr>
      <qgc_udp_port>14550</qgc_udp_port>
      <sdk_addr>INADDR_ANY</sdk_addr>
      <sdk_udp_port>14540</sdk_udp_port>
      <hil_mode>0</hil_mode>
      <hil_state_level>false</hil_state_level>
      <enable_lockstep>true</enable_lockstep>
      <use_tcp>true</use_tcp>
      <motorSpeedCommandPubTopic>/gazebo/command/motor_speed</motorSpeedCommandPubTopic>
      <control_channels>
        <channel name="rotor_1">
          <input_index>0</input_index>
          <input_offset>0</input_offset>
          <input_scaling>100</input_scaling>
          <zero_position_disarmed>0</zero_position_disarmed>
          <zero_position_armed>0</zero_position_armed>
          <joint_control_type>velocity</joint_control_type>
          <joint_name>Engine_helice_1</joint_name>
        </channel>
        <channel name="rotor_2">
          <input_index>1</input_index>
          <input_offset>0</input_offset>
          <input_scaling>100</input_scaling>
          <zero_position_disarmed>0</zero_position_disarmed>
          <zero_position_armed>0</zero_position_armed>
          <joint_control_type>velocity</joint_control_type>
          <joint_name>Engine_helice_2</joint_name>
        </channel>
        <channel name="rotor_3">
          <input_index>2</input_index>
          <input_offset>0</input_offset>
          <input_scaling>100</input_scaling>
          <zero_position_disarmed>0</zero_position_disarmed>
          <zero_position_armed>0</zero_position_armed>
          <joint_control_type>velocity</joint_control_type>
          <joint_name>Engine_helice_3</joint_name>
        </channel>
        <channel name="rotor_4">
          <input_index>3</input_index>
          <input_offset>0</input_offset>
          <input_scaling>100</input_scaling>
          <zero_position_disarmed>0</zero_position_disarmed>
          <zero_position_armed>0</zero_position_armed>
          <joint_control_type>velocity</joint_control_type>
          <joint_name>Engine_helice_4</joint_name>
        </channel>
      </control_channels>
    </plugin>

  </model>
</sdf>
